<?xml version="1.0" ?>
<robot name="arm-assembly">

  <link name="base_link">
  </link>

  <!-- Link dcmotor -->
  <link name="dcmotor">
    <inertial>
      <origin xyz="2.29639e-05 -9.97032e-09 0.0848675" rpy="0 0 0"/>
      <mass value="1.18635"/>
      <inertia ixx="0.00111316" ixy="3.28229e-11" ixz="-1.39348e-06" iyy="0.001113" iyz="4.61981e-10" izz="0.000283958"/>
    </inertial>
    <!-- Part mechenical_lock -->
    <visual>
      <origin xyz="0 0 0" rpy="0 -0 0"/>
      <geometry>
        <mesh filename="file://$(find arm_assembly)/assets/mechenical_lock.stl"/>
      </geometry>
      <material name="mechenical_lock_material">
        <color rgba="0.627451 0.627451 0.627451 1"/>
      </material>
    </visual>
    <collision>
      <origin xyz="0 0 0" rpy="0 -0 0"/>
      <geometry>
        <mesh filename="file://$(find arm_assembly)/assets/mechenical_lock.stl"/>
      </geometry>
    </collision>
    <!-- Part dcmotor -->
    <visual>
      <origin xyz="0 0 0" rpy="0 -0 0"/>
      <geometry>
        <mesh filename="file://$(find arm_assembly)/assets/dcmotor.stl"/>
      </geometry>
      <material name="dcmotor_material">
        <color rgba="0.776471 0.756863 0.737255 1"/>
      </material>
    </visual>
    <collision>
      <origin xyz="0 0 0" rpy="0 -0 0"/>
      <geometry>
        <mesh filename="file://$(find arm_assembly)/assets/dcmotor.stl"/>
      </geometry>
    </collision>
  </link>
  <!-- Link motor_shaft -->
  <link name="motor_shaft">
    <inertial>
      <origin xyz="0.124219 -0.00145334 -0.0293684" rpy="0 0 0"/>
      <mass value="0.299432"/>
      <inertia ixx="8.47911e-05" ixy="2.77625e-05" ixz="0.000179333" iyy="0.00189854" iyz="-4.35859e-06" izz="0.00188224"/>
    </inertial>
    <!-- Part motor_mount -->
    <visual>
      <origin xyz="0 0 0.135" rpy="3.14159 -0 0"/>
      <geometry>
        <mesh filename="file://$(find arm_assembly)/assets/motor_mount.stl"/>
      </geometry>
      <material name="motor_mount_material">
        <color rgba="0.627451 0.627451 0.627451 1"/>
      </material>
    </visual>
    <collision>
      <origin xyz="0 0 0.135" rpy="3.14159 -0 0"/>
      <geometry>
        <mesh filename="file://$(find arm_assembly)/assets/motor_mount.stl"/>
      </geometry>
    </collision>
    <!-- Part link1 -->
    <visual>
      <origin xyz="0.00270197 5e-05 0.135" rpy="3.14159 4.93958e-44 2.72157e-29"/>
      <geometry>
        <mesh filename="file://$(find arm_assembly)/assets/link1.stl"/>
      </geometry>
      <material name="link1_material">
        <color rgba="0.627451 0.627451 0.627451 1"/>
      </material>
    </visual>
    <collision>
      <origin xyz="0.00270197 5e-05 0.135" rpy="3.14159 4.93958e-44 2.72157e-29"/>
      <geometry>
        <mesh filename="file://$(find arm_assembly)/assets/link1.stl"/>
      </geometry>
    </collision>
    <!-- Part motor_shaft -->
    <visual>
      <origin xyz="0 0 0.135" rpy="3.14159 -0 0"/>
      <geometry>
        <mesh filename="file://$(find arm_assembly)/assets/motor_shaft.stl"/>
      </geometry>
      <material name="motor_shaft_material">
        <color rgba="0.792157 0.819608 0.933333 1"/>
      </material>
    </visual>
    <collision>
      <origin xyz="0 0 0.135" rpy="3.14159 -0 0"/>
      <geometry>
        <mesh filename="file://$(find arm_assembly)/assets/motor_shaft.stl"/>
      </geometry>
    </collision>
    <!-- Part servo_mount -->
    <visual>
      <origin xyz="0.00350197 0.00594864 0.135272" rpy="3.10669 1.13602e-14 -3.96706e-16"/>
      <geometry>
        <mesh filename="file://$(find arm_assembly)/assets/servo_mount.stl"/>
      </geometry>
      <material name="servo_mount_material">
        <color rgba="0.501961 0.501961 0.501961 1"/>
      </material>
    </visual>
    <collision>
      <origin xyz="0.00350197 0.00594864 0.135272" rpy="3.10669 1.13602e-14 -3.96706e-16"/>
      <geometry>
        <mesh filename="file://$(find arm_assembly)/assets/servo_mount.stl"/>
      </geometry>
    </collision>
    <!-- Part extrusion_mount -->
    <visual>
      <origin xyz="-5.20417e-17 1.16567e-31 0.135" rpy="3.14159 -0 0"/>
      <geometry>
        <mesh filename="file://$(find arm_assembly)/assets/extrusion_mount.stl"/>
      </geometry>
      <material name="extrusion_mount_material">
        <color rgba="0.627451 0.627451 0.627451 1"/>
      </material>
    </visual>
    <collision>
      <origin xyz="-5.20417e-17 1.16567e-31 0.135" rpy="3.14159 -0 0"/>
      <geometry>
        <mesh filename="file://$(find arm_assembly)/assets/extrusion_mount.stl"/>
      </geometry>
    </collision>
    <!-- Part servo -->
    <visual>
      <origin xyz="0.00350197 0.00594864 0.135272" rpy="3.10669 1.16211e-14 7.07643e-15"/>
      <geometry>
        <mesh filename="file://$(find arm_assembly)/assets/servo.stl"/>
      </geometry>
      <material name="servo_material">
        <color rgba="0.627451 0.627451 0.627451 1"/>
      </material>
    </visual>
    <collision>
      <origin xyz="0.00350197 0.00594864 0.135272" rpy="3.10669 1.16211e-14 7.07643e-15"/>
      <geometry>
        <mesh filename="file://$(find arm_assembly)/assets/servo.stl"/>
      </geometry>
    </collision>
  </link>
  <!-- Link servo_to_extrusion_mount -->
  <link name="servo_to_extrusion_mount">
    <inertial>
      <origin xyz="0.0692591 -2.38882e-05 -0.0194633" rpy="0 0 0"/>
      <mass value="0.183179"/>
      <inertia ixx="1.69101e-05" ixy="1.41052e-08" ixz="7.44392e-06" iyy="0.00134282" iyz="-2.55332e-09" izz="0.00134148"/>
    </inertial>
    <!-- Part extrusion_mount_2 -->
    <visual>
      <origin xyz="-0.17395 0.1802 0.0237" rpy="1.5708 4.55532e-16 -2.67184e-24"/>
      <geometry>
        <mesh filename="file://$(find arm_assembly)/assets/extrusion_mount_2.stl"/>
      </geometry>
      <material name="extrusion_mount_2_material">
        <color rgba="0.627451 0.627451 0.627451 1"/>
      </material>
    </visual>
    <collision>
      <origin xyz="-0.17395 0.1802 0.0237" rpy="1.5708 4.55532e-16 -2.67184e-24"/>
      <geometry>
        <mesh filename="file://$(find arm_assembly)/assets/extrusion_mount_2.stl"/>
      </geometry>
    </collision>
    <!-- Part link2 -->
    <visual>
      <origin xyz="-0.17395 0.1802 0.02365" rpy="1.5708 4.55532e-16 -2.67209e-24"/>
      <geometry>
        <mesh filename="file://$(find arm_assembly)/assets/link2.stl"/>
      </geometry>
      <material name="link2_material">
        <color rgba="0.627451 0.627451 0.627451 1"/>
      </material>
    </visual>
    <collision>
      <origin xyz="-0.17395 0.1802 0.02365" rpy="1.5708 4.55532e-16 -2.67209e-24"/>
      <geometry>
        <mesh filename="file://$(find arm_assembly)/assets/link2.stl"/>
      </geometry>
    </collision>
    <!-- Part servo_horn -->
    <visual>
      <origin xyz="-0.17395 0.1802 0.0237" rpy="1.5708 4.55532e-16 -1.92285e-30"/>
      <geometry>
        <mesh filename="file://$(find arm_assembly)/assets/servo_horn.stl"/>
      </geometry>
      <material name="servo_horn_material">
        <color rgba="0.627451 0.627451 0.627451 1"/>
      </material>
    </visual>
    <collision>
      <origin xyz="-0.17395 0.1802 0.0237" rpy="1.5708 4.55532e-16 -1.92285e-30"/>
      <geometry>
        <mesh filename="file://$(find arm_assembly)/assets/servo_horn.stl"/>
      </geometry>
    </collision>
    <!-- Part servo_to_extrusion_mount -->
    <visual>
      <origin xyz="-0.17395 0.1802 0.0237" rpy="1.5708 4.55532e-16 -1.96525e-28"/>
      <geometry>
        <mesh filename="file://$(find arm_assembly)/assets/servo_to_extrusion_mount.stl"/>
      </geometry>
      <material name="servo_to_extrusion_mount_material">
        <color rgba="0.627451 0.627451 0.627451 1"/>
      </material>
    </visual>
    <collision>
      <origin xyz="-0.17395 0.1802 0.0237" rpy="1.5708 4.55532e-16 -1.96525e-28"/>
      <geometry>
        <mesh filename="file://$(find arm_assembly)/assets/servo_to_extrusion_mount.stl"/>
      </geometry>
    </collision>
  </link>
  <!-- Joint from motor_shaft to servo_to_extrusion_mount -->
  <joint name="servo_horn_to_servo" type="revolute">
    <origin xyz="0.177452 0.0224459 -0.0456137" rpy="1.53589 1.16052e-14 6.62118e-15"/>
    <parent link="motor_shaft"/>
    <child link="servo_to_extrusion_mount"/>
    <axis xyz="0 0 1"/>
    <limit effort="10" velocity="10" lower="-3.14159" upper="1.5708"/>
  </joint>
  <!-- Joint from dcmotor to motor_shaft -->
  <joint name="link1_to_base" type="revolute">
    <origin xyz="-5.48685e-05 1.88019e-19 0.135" rpy="3.14159 -0 0"/>
    <parent link="dcmotor"/>
    <child link="motor_shaft"/>
    <axis xyz="0 0 1"/>
    <limit effort="10" velocity="10" lower="-0.785398" upper="0.785398"/>
  </joint>


  <joint name="dcmotor_to_base_link" type="fixed">
    <origin xyz="0 0 0" rpy="0 0 0"/>
    <parent link="dcmotor"/>
    <child link="base_link"/>
  </joint>


</robot>